[2025-03-13T12:26:42.562+0000] {taskinstance.py:1956} INFO - Dependencies all met for dep_context=non-requeueable deps ti=<TaskInstance: etl_multi_source.load_task manual__2025-03-13T12:26:38.639842+00:00 [queued]>
[2025-03-13T12:26:42.569+0000] {taskinstance.py:1956} INFO - Dependencies all met for dep_context=requeueable deps ti=<TaskInstance: etl_multi_source.load_task manual__2025-03-13T12:26:38.639842+00:00 [queued]>
[2025-03-13T12:26:42.570+0000] {taskinstance.py:2170} INFO - Starting attempt 1 of 2
[2025-03-13T12:26:42.581+0000] {taskinstance.py:2191} INFO - Executing <Task(PythonOperator): load_task> on 2025-03-13 12:26:38.639842+00:00
[2025-03-13T12:26:42.586+0000] {standard_task_runner.py:60} INFO - Started process 388 to run task
[2025-03-13T12:26:42.589+0000] {standard_task_runner.py:87} INFO - Running: ['***', 'tasks', 'run', 'etl_multi_source', 'load_task', 'manual__2025-03-13T12:26:38.639842+00:00', '--job-id', '36', '--raw', '--subdir', 'DAGS_FOLDER/etl_multi_source.py', '--cfg-path', '/tmp/tmp3bwopfdq']
[2025-03-13T12:26:42.591+0000] {standard_task_runner.py:88} INFO - Job 36: Subtask load_task
[2025-03-13T12:26:42.629+0000] {task_command.py:423} INFO - Running <TaskInstance: etl_multi_source.load_task manual__2025-03-13T12:26:38.639842+00:00 [running]> on host 029b78518459
[2025-03-13T12:26:42.687+0000] {taskinstance.py:2480} INFO - Exporting env vars: AIRFLOW_CTX_DAG_OWNER='***' AIRFLOW_CTX_DAG_ID='etl_multi_source' AIRFLOW_CTX_TASK_ID='load_task' AIRFLOW_CTX_EXECUTION_DATE='2025-03-13T12:26:38.639842+00:00' AIRFLOW_CTX_TRY_NUMBER='1' AIRFLOW_CTX_DAG_RUN_ID='manual__2025-03-13T12:26:38.639842+00:00'
[2025-03-13T12:26:42.934+0000] {taskinstance.py:2698} ERROR - Task failed with exception
Traceback (most recent call last):
  File "/home/airflow/.local/lib/python3.8/site-packages/airflow/models/taskinstance.py", line 433, in _execute_task
    result = execute_callable(context=context, **execute_callable_kwargs)
  File "/home/airflow/.local/lib/python3.8/site-packages/airflow/operators/python.py", line 199, in execute
    return_value = self.execute_callable()
  File "/home/airflow/.local/lib/python3.8/site-packages/airflow/operators/python.py", line 216, in execute_callable
    return self.python_callable(*self.op_args, **self.op_kwargs)
  File "/opt/airflow/dags/etl_multi_source.py", line 170, in combine_and_load_data
    df_csv.to_sql('penduduk', conn, if_exists='replace', index=False)
  File "/home/airflow/.local/lib/python3.8/site-packages/pandas/core/generic.py", line 2878, in to_sql
    return sql.to_sql(
  File "/home/airflow/.local/lib/python3.8/site-packages/pandas/io/sql.py", line 769, in to_sql
    return pandas_sql.to_sql(
  File "/home/airflow/.local/lib/python3.8/site-packages/pandas/io/sql.py", line 2378, in to_sql
    table.create()
  File "/home/airflow/.local/lib/python3.8/site-packages/pandas/io/sql.py", line 914, in create
    self._execute_create()
  File "/home/airflow/.local/lib/python3.8/site-packages/pandas/io/sql.py", line 2052, in _execute_create
    conn.execute(stmt)
sqlite3.OperationalError: table "penduduk" already exists
[2025-03-13T12:26:42.947+0000] {taskinstance.py:1138} INFO - Marking task as UP_FOR_RETRY. dag_id=etl_multi_source, task_id=load_task, execution_date=20250313T122638, start_date=20250313T122642, end_date=20250313T122642
[2025-03-13T12:26:42.956+0000] {standard_task_runner.py:107} ERROR - Failed to execute job 36 for task load_task (table "penduduk" already exists; 388)
[2025-03-13T12:26:43.001+0000] {local_task_job_runner.py:234} INFO - Task exited with return code 1
[2025-03-13T12:26:43.017+0000] {taskinstance.py:3280} INFO - 0 downstream tasks scheduled from follow-on schedule check
